<script>
window.addEventListener('DOMContentLoaded', async(e)=>{
/*
async function checkAge(age) {
    if(Number.isInteger(age) && 0<=age && age<=100){resolve(age)}
    else{reject(new TypeError(`第一引数ageは年齢を表す0以上100以下の整数値であるべきです。`))}
}
*/
/*
const checkAge = (age)=>new Promise((resolve, reject)=>{
    if(Number.isInteger(age) && 0<=age && age<=100){resolve(age)}
    else{reject(new TypeError(`第一引数ageは年齢を表す0以上100以下の整数値であるべきです。`))}
})

checkAge(0).then(age=>console.log(`年齢: ${age}`)).catch(e=>console.error(e))
checkAge(100).then(age=>console.log(`年齢: ${age}`)).catch(e=>console.error(e))
checkAge(-1).then(age=>console.log(`年齢: ${age}`)).catch(e=>console.error(e))
checkAge(101).then(age=>console.log(`年齢: ${age}`)).catch(e=>console.error(e))
checkAge('A').then(age=>console.log(`年齢: ${age}`)).catch(e=>console.error(e))

const age = checkAge(0)
*/

class TestTarget {
    getTrue() { return true }
    getFalse() { return false }
    throwError() { throw new Error('例外を投げます。') }
    async getTrueAsync() { return new Promise((resolve)=>resolve(true)) }
    async getFalseAsync() { return new Promise((resolve)=>resolve(false)) }
    async throwErrorAsync() { return new Promise((resolve)=>resolve(new Error('例外を投げます。'))) }
    isAge(age) { return Number.isInteger(age) && 0<=age && age<=100 }
    async isAgeAsync(age) { return new Promise((resolve, reject)=>{
        if (Number.isInteger(age) && 0<=age && age<=100) {resolve(age)}
        else{reject(new TypeError(`第一引数ageは年齢を表す0以上100以下の整数値であるべきです。`))}
    }) }
}
class Assertion {
//    static t(v) { return  this._getActual(v,true) }
//    static f(v) { return !this._getActual(v,true) }
//    static t(v) { return  this._normal(v) }
//    static f(v) { return !this._normal(v, true) }
    static t(v) { const r=this._normal(v); if(!r){this._result('テスト失敗。真であるべき所が偽である。')}; return  r; }
    static f(v) { const r=this._normal(v); console.log(v,r);if( r){this._result('テスト失敗。偽であるべき所が真である。')}; return !r; }
//    static f(v) { const r=this._normal(v,true); if(!r){this._result('テスト失敗。偽であるべき所が真である。')}; return r; }
    static e(type, msg, fn) {
        try {
            this._getActual(fn)
//            throw new Error(`例外発生すべき所で例外発生せず正常終了した。`, err)
        }
        catch (err) {
            const cslMsg = Assertion._makeErrorMessage(type, msg, err)
            if (cslMsg) { console.error(cslMsg, err); return false; }
            return true
        }
    }

//    static _normal(v, isFalseSuccess) { // 正常系（例外発生しない）
//        try { return this._getActual(v, true) }
//        catch (err) { throw new Error(`正常終了すべき所で例外発生した。`, err) }
//    }
    static _normal(v, isFalseSuccess) { // 正常系（例外発生しない）
//        try { return this._getActual(v, true) }
        try { const a=this._getActual(v, true); return isFalseSuccess ? !a : a }
        catch (err) { throw new Error(`正常終了すべき所で例外発生した。`, err) }
    }
    static _getActual(v, acceptBool) {
        switch (typeof v) {
            case 'function': return v()
            case 'boolean': {if(acceptBool){return v}else{throw new Error(`不正な引数値です。関数のみ有効です。`)}}//return acceptBool ? v : 
            default: throw new Error(`不正な引数値です。関数か真偽値のみ有効です。`)
        }
    }
    static _resolvePromiseNormal(v) {
        if (v instanceof Promise) {
//            v.resolve(target)
            try { return v.resolve() }
            catch (err) { this._fail('テスト失敗。プロミスにて真偽値を返すべき所で例外発生した。', this._resolvePromiseNormal) }
        }
    }
    static _resolvePromiseError(v) {
        if (v instanceof Promise) {
            v.then((res)=>res).catch(e=>)
        }
    }
    //static _result(msg, caller) {
    static _fail(msg, caller) {
        if (Error.captureStackTrace) {
            Error.captureStackTrace(this, caller ?? this._result);
            console.error(msg + '\n', this.stack)
        } else { console.error(msg) }

    }
 }
const t = new TestTarget()
Assertion.t(t.getTrue())
Assertion.t(()=>t.getTrue())
Assertion.t(async()=>await t.getTrueAsync())
Assertion.f(t.getFalse())
Assertion.f(()=>t.getFalse())
Assertion.f(async()=>await t.getFalseAsync())
Assertion.e(t.throwError())


Assertion.t(t.getTrue())
/*
const testT = (...args)=>new Promise((resolve, reject)=>{
    try {
        const actual = resolve(...args)
    } catch(err) {

    }
    if(Number.isInteger(age) && 0<=age && age<=100){resolve(age)}
    else{reject(new TypeError(`第一引数ageは年齢を表す0以上100以下の整数値であるべきです。`))}
})
a.t(async(target)=await target.trueAsync())
*/
/*
checkAge(0).then(age=>console.log(`年齢: ${age}`)).catch(e=>console.error(e))
checkAge(100).then(age=>console.log(`年齢: ${age}`)).catch(e=>console.error(e))
checkAge(-1).then(age=>console.log(`年齢: ${age}`)).catch(e=>console.error(e))
checkAge(101).then(age=>console.log(`年齢: ${age}`)).catch(e=>console.error(e))
checkAge('A').then(age=>console.log(`年齢: ${age}`)).catch(e=>console.error(e))
*/

})
</script>
