<script>
window.addEventListener('DOMContentLoaded', async(e)=>{
class TestTarget {
    getTrue() { return true }
    getFalse() { return false }
    throwError() { throw new Error('例外を投げます。') }
    async getTrueAsync() { return new Promise((resolve)=>resolve(true)) }
    async getFalseAsync() { return new Promise((resolve)=>resolve(false)) }
    async throwErrorAsync() { return new Promise((resolve)=>resolve(new Error('例外を投げます。'))) }
    isAge(age) { return Number.isInteger(age) && 0<=age && age<=100 }
    async isAgeAsync(age) { return new Promise((resolve, reject)=>{
        if (Number.isInteger(age) && 0<=age && age<=100) {resolve(age)}
        else{reject(new TypeError(`第一引数ageは年齢を表す0以上100以下の整数値であるべきです。`))}
    }) }
}
class AssertError extends Error {
    constructor(msg, cause) {
        super(msg, {cause,cause});
        this.name = 'AssertError';
        this.cause = cause;
    }
}
class BaseAssertion {
    static _consoleFail(msg, caller) {
        if (Error.captureStackTrace) {
            Error.captureStackTrace(this, caller ?? this._result);
            console.error(msg + '\n', this.stack)
        } else { console.error(msg) }

    }
    static _consoleError(msg, err, caller) {
        if (Error.captureStackTrace) {
            const errs = this._recursionCause([err])
            const init = []
            const errsNl = [msg, ...errs].reduce((a,v)=>{a.push(v);a.push('\n');return a;},init)
            errsNl.pop()
            console.error(...errsNl)
        } else { console.error(msg) }
    }
    static _recursionCause(errs) {
        const last = errs[errs.length-1]
        if (last.hasOwnProperty('cause') && last.cause) {
            errs.push(last.cause)
            return this._recursionCause(errs)
        } else { return errs }
    }
    static __isBool(v) { return 'boolean'===typeof v }
    static __isFn(v) { return 'function'===typeof v }
    static __isStr(v) { return 'string'===typeof v || v instanceof String }
    static __isAsyncFunction(v) { return v instanceof (async()=>{}).constructor }
    static __isNullOrUndefined(v) {
        if (v === null) return true;
        if(v === undefined) return true;
        return false;
    }
    static __isGenealogy(a, e) { // aがeの系譜（同一または子孫クラス）であれば真を返す
        if (a instanceof e || a.constructor.name === e.constructor.name) { return true }
        if (a.prototype) { return this.__isGenealogy(a.prototype, e) }
        return false
    }
}
class NormalAssertion extends BaseAssertion {
    static t(fn) { this._normal(fn) }
    static f(fn) { this._normal(fn, true) }
    static _normal(fn, isFalseSuccess) {
        if (fn instanceof this._AsyncFunction) { this._nAsync(fn, isFalseSuccess) }
        else if (this.__isFn(fn)) { this._nFn(fn, isFalseSuccess) }
        else if (this.__isBool(fn)) { this._nB(fn, isFalseSuccess) }
//        else if ('function'===typeof fn) { this._nFn(fn, isFalseSuccess) }
//        else if ('boolean'===typeof fn) { this._nB(fn, isFalseSuccess) }
        else { this._consoleFail(`引数は真偽値かそれを返す関数であるべきです。`, this.t) }
    }
    static _nAsync(fn, isFalseSuccess) {
        fn().then((bool)=>{
            this.__nCheck(bool, isFalseSuccess)
        }).catch(err=>{
            this.__failMsgErr(isFalseSuccess, err)
        })
    }
    static _nFn(fn, isFalseSuccess) {
        try {
            const bool = fn()
            this.__nCheck(bool, isFalseSuccess)
        } catch(err) {
            this.__failMsgErr(isFalseSuccess, err)
        }
    }
    static _nB(fn, isFalseSuccess) {
        if (isFalseSuccess ? fn : !fn) { this._consoleFail(this.__failMsg(isFalseSuccess), this.t) }
    }
    static __nCheck(bool, isFalseSuccess) {
        //if ('boolean'!==typeof bool) { return this._consoleFail('テストコードは最後に真偽値を返してください。', this.t) }
        if (this.__isBool(bool)) { return this._consoleFail('テストコードは最後に真偽値を返してください。', this.t) }
        if (isFalseSuccess ? bool : !bool) { return this._consoleFail(this.__failMsg(isFalseSuccess), this.t) }
    }
    static __failMsg(isFalseSuccess) {
        const j = ['真','偽']
        if (isFalseSuccess) { j.reverse() }
        return `${j[0]}であるべき所が${j[1]}です。`
    }
    static __failMsgErr(isFalseSuccess, err) { this._consoleError(`${isFalseSuccess ? '偽' : '真'}であるべき所で例外発生しました。`, err, this.t) }
}
class ErrorAssertion extends BaseAssertion {
    static e(type, msg, fn) {
        if (this._ePrmErr(type, msg, fn)) return
        return this._error(type, msg, fn)
    }
    static _ePrmErr(type, msg, fn) {
        let eMsgs = []
        if ([type,msg,fn].some(v=>this.__isNullOrUndefined(v))) { eMsgs.push(`引数は次の3つ必要です:\n1. 期待する例外型\n2. 期待する例外メッセージ(String/RegExp)\n3. 例外発生する無名関数`) }
        if (!this.__isGenealogy(type, Error)) { eMsgs.push(`第一引数は期待する例外型でありErrorかそれを継承した型であるべきです。`) }
        if (!this.__isStr(msg)) { eMsgs.push(`第二引数は期待する例外メッセージを示す文字列型Stringか正規表現RegExp型であるべきです。`) }
        if (!(this.__isAsyncFunction(fn)) && 'function'!==typeof fn) {eMsgs.push(`第三引数は例外を発生させる関数であるべきです。`)}
        if (0<eMsgs.length) {
            this._consoleFail('引数不正です。\n' + eMsgs.join('\n'), this.t)
            return true
        }
    }
    static _error(type, msg, fn) {
        if (this.__isAsyncFunction(fn)) { this._eAsync(type, msg, fn) }
        else if (this.__isFn(fn)) { this._eFn(type, msg, fn) }
        else { this._consoleFail(`引数は例外を発生させる関数であるべきです。`, this.t) }
    }
    static _eAsync(type, msg, fn) {
        fn().then((bool)=>{
            this._consoleFail(this.__errorMsg(), this.t)
        }).catch(err=>{
            this.__eCheck(type, msg, err)
        })
    }
    static _eFn(type, msg, fn) {
        try {
            const bool = fn()
            this._consoleFail(this.__errorMsg(), this.t)

        } catch(err) {
            this.__eCheck(type, msg, err)
        }
    }
    static __
    static __eCheck(type, msg, err) {
        console.log(type, msg, err)
        const eMsgs = [this.__eCheckTypeMsg(type, err), this.__eCheckMsgMsg(msg, err)].filter(v=>v)
        if (0<eMsgs.length) this._consoleFail(`テスト失敗: ${2<=eMsgs.length ? '\n' : ''}${eMsgs.join('\n')}`, this.t)
    }
    static __eCheckTypeMsg(type, err) {
//        if (err instanceof type) { return '' }
//        return `型が違います。\n期待値: ${type}\n実際値: ${err.constructor.name}`
        if (err.constructor.name === type.name) { return '' }
        return `型が違います。\n期待値: ${type.name}\n実際値: ${err.constructor.name}`
    }
    static __eCheckMsgMsg(msg, err) {
        if (msg instanceof RegExp) {
            if (msg.test(msg)) { return '' }
            return `メッセージが違います。\n期待値: ${msg}\n実際値: ${err.message}`
        }
        if ('string'===typeof msg || msg instanceof String) {
            if (msg===err.message) { return '' }
            return `メッセージが違います。\n期待値: ${msg}\n実際値: ${err.message}`
        }
        throw new AssertError(`メッセージの型は文字列Stringか正規表現RegExpのいずれかのみ有効です。`)
    }
    static __errorMsg() { return `例外発生すべき所で例外発生せず正常終了しました。` }
    static __errorMsgErr(isFalseSuccess, err) { this._consoleError(`${isFalseSuccess ? '偽' : '真'}であるべき所で例外発生しました。`, err, this.t) }
}
class Assertion {
    constructor() {
        this._count = {success:0, fail:0}
        this._AsyncFunction = (async()=>{}).constructor
    }
    t(fn) { NormalAssertion.t(fn) }
    f(fn) { NormalAssertion.f(fn) }
    e(type, msg, fn) { ErrorAssertion.e(type, msg, fn) }
}
const t = new TestTarget()
const a = new Assertion()

console.log(Error.name)
console.log(Error.constructor.name)
console.log(new Error().name)
a.e(true) // 引数不正です。
a.e(false) // 引数不正です。
a.e(()=>true) // 引数不正です。
a.e(1, 2, 3) // 引数不正です。
a.e(1, '', ()=>{}) // 引数不正です。
a.e(Error, 2, ()=>{}) // 引数不正です。
a.e(Error, '', 3) // 引数不正です。
a.e(1, 2, ()=>{}) // 引数不正です。
a.e(1, '', 3) // 引数不正です。
a.e(Error, 2, 3) // 引数不正です。
a.e(Error, '', ()=>{}) // 例外発生すべき所で例外発生せず正常終了しました。
a.e(Error, '', ()=>{throw new Error})
a.e(Error, '', ()=>{throw new TypeError}) // 
a.e(Error, '', ()=>{throw new Error('')})
a.e(Error, 'A', ()=>{throw new Error('A')})
a.e(Error, 'A', ()=>{throw new Error('A')}) // テスト失敗: メッセージが違います。
a.e(Error, 'A', ()=>{throw new Error('B')}) // テスト失敗: メッセージが違います。
a.e(Error, '', ()=>{throw new TypeError}) // テスト失敗: 型が違います。
a.e(TypeError, '', ()=>{throw new Error}) // テスト失敗: 型が違います。
a.e(TypeError, '', ()=>{throw new TypeError})
a.e(TypeError, 'A', ()=>{throw new TypeError('A')})
a.e(TypeError, 'A', ()=>{throw new TypeError('B')}) // テスト失敗: メッセージが違います。
a.e(Error, 'A', ()=>{throw new TypeError('B')}) // テスト失敗: 型が違います。...メッセージが違います。...


/*
a.t(async()=>await t.getTrueAsync())
a.t(async()=>await t.getFalseAsync())
a.t(async()=>await t.throwErrorAsync())
a.t(()=>t.getTrue())
a.t(()=>t.getFalse())
a.t(()=>t.throwError())
a.t(t.getTrue())
a.t(t.getFalse())
a.t(t.throwError()) // 例外が起きた時キャッチできないが、それはどこでも同じ
a.t(0)
*/
/*
a.f(async()=>await t.getTrueAsync())
a.f(async()=>await t.getFalseAsync())
a.f(async()=>await t.throwErrorAsync())
a.f(()=>t.getTrue())
a.f(()=>t.getFalse())
a.f(()=>t.throwError())
a.f(t.getTrue())
a.f(t.getFalse())
a.f(t.throwError()) // 例外が起きた時キャッチできないが、それはどこでも同じ
a.f(0)
*/
/*
*/


/*
a.t(true)
a.t(()=>true)
//a.t(t.getTrueAsync())
a.t(await t.getTrueAsync())
//a.t(async()=>await t.getTrueAsync())
//a.t(()=>{async()=>await t.getTrueAsync()})
//a.t(()=>{
//    const res = await t.getTrueAsync() // SyntaxError: await is only valid in async functions and the top level bodies of modules
//    return res
//})
a.t(async()=>{
    const res = await t.getTrueAsync() // SyntaxError: await is only valid in async functions and the top level bodies of modules
    return res
})


a.t(t.getTrue())
//a.t(t.getTrueAsync())
a.t(await t.getTrueAsync())
//a.t(async()=>await t.getTrueAsync())

//a.t(()=>await true)
//a.t(async()=>await true)
//a.t(false)
//a.t(()=>false)
//a.t(()=>await false)
//a.t(async()=>await false)
*/



/*
class Assertion {
//    static t(v) { return  this._getActual(v,true) }
//    static f(v) { return !this._getActual(v,true) }
//    static t(v) { return  this._normal(v) }
//    static f(v) { return !this._normal(v, true) }
    static t(v) { const r=this._normal(v); if(!r){this._result('テスト失敗。真であるべき所が偽である。')}; return  r; }
    static f(v) { const r=this._normal(v); console.log(v,r);if( r){this._result('テスト失敗。偽であるべき所が真である。')}; return !r; }
//    static f(v) { const r=this._normal(v,true); if(!r){this._result('テスト失敗。偽であるべき所が真である。')}; return r; }
    static e(type, msg, fn) {
        try {
            this._getActual(fn)
//            throw new Error(`例外発生すべき所で例外発生せず正常終了した。`, err)
        }
        catch (err) {
            const cslMsg = Assertion._makeErrorMessage(type, msg, err)
            if (cslMsg) { console.error(cslMsg, err); return false; }
            return true
        }
    }

//    static _normal(v, isFalseSuccess) { // 正常系（例外発生しない）
//        try { return this._getActual(v, true) }
//        catch (err) { throw new Error(`正常終了すべき所で例外発生した。`, err) }
//    }
    static _normal(v, isFalseSuccess) { // 正常系（例外発生しない）
//        try { return this._getActual(v, true) }
        try { const a=this._getActual(v, true); return isFalseSuccess ? !a : a }
        catch (err) { throw new Error(`正常終了すべき所で例外発生した。`, err) }
    }
    static _getActual(v, acceptBool) {
        switch (typeof v) {
            case 'function': return v()
            case 'boolean': {if(acceptBool){return v}else{throw new Error(`不正な引数値です。関数のみ有効です。`)}}//return acceptBool ? v : 
            default: throw new Error(`不正な引数値です。関数か真偽値のみ有効です。`)
        }
    }
    static _resolvePromiseNormal(v) {
        if (v instanceof Promise) {
//            v.resolve(target)
            try { return v.resolve() }
            catch (err) { this._fail('テスト失敗。プロミスにて真偽値を返すべき所で例外発生した。', this._resolvePromiseNormal) }
        }
    }
    static _resolvePromiseError(v) {
        if (v instanceof Promise) {
            v.then((res)=>res).catch(e=>)
        }
    }
    //static _result(msg, caller) {
    static _fail(msg, caller) {
        if (Error.captureStackTrace) {
            Error.captureStackTrace(this, caller ?? this._result);
            console.error(msg + '\n', this.stack)
        } else { console.error(msg) }

    }
 }
const t = new TestTarget()
Assertion.t(t.getTrue())
Assertion.t(()=>t.getTrue())
Assertion.t(async()=>await t.getTrueAsync())
Assertion.f(t.getFalse())
Assertion.f(()=>t.getFalse())
Assertion.f(async()=>await t.getFalseAsync())
Assertion.e(t.throwError())

Assertion.t(t.getTrue())
*/
/*
const testT = (...args)=>new Promise((resolve, reject)=>{
    try {
        const actual = resolve(...args)
    } catch(err) {

    }
    if(Number.isInteger(age) && 0<=age && age<=100){resolve(age)}
    else{reject(new TypeError(`第一引数ageは年齢を表す0以上100以下の整数値であるべきです。`))}
})
a.t(async(target)=await target.trueAsync())
*/
/*
checkAge(0).then(age=>console.log(`年齢: ${age}`)).catch(e=>console.error(e))
checkAge(100).then(age=>console.log(`年齢: ${age}`)).catch(e=>console.error(e))
checkAge(-1).then(age=>console.log(`年齢: ${age}`)).catch(e=>console.error(e))
checkAge(101).then(age=>console.log(`年齢: ${age}`)).catch(e=>console.error(e))
checkAge('A').then(age=>console.log(`年齢: ${age}`)).catch(e=>console.error(e))
*/

})
</script>
